<?xml version="1.0" ?>
<!-- =================================================================================== -->
<!-- |    This document was autogenerated by xacro from princeton_3rob_cell.xacro      | -->
<!-- |    EDITING THIS FILE BY HAND IS NOT RECOMMENDED                                 | -->
<!-- =================================================================================== -->
<robot name="princeton_3rob_cell">
  <!-- Conversion were obtained from http://www.e-paint.co.uk/Lab_values.asp
       unless otherwise stated. -->
  <link name="world"/>
  <!-- -->
  <!--ROBOT 1-->
  <joint name="r1_world_joint" type="fixed">
    <parent link="world"/>
    <child link="r1_axis"/>
    <origin rpy="0.0 0.0 3.14159" xyz="3.6986 3.4507 0.015"/>
  </joint>
  <!-- Conversion were obtained from http://www.e-paint.co.uk/Lab_values.asp
       unless otherwise stated. -->
  <!-- Conversion were obtained from http://www.e-paint.co.uk/Lab_values.asp
       unless otherwise stated. -->
  <!-- LINEAR AXIS -->
  <!-- linear axis link list -->
  <link name="r1_axis">
    <inertial>
      <origin xyz="0.0 0.0 0.0"/>
      <mass value="120"/>
      <inertia ixx="-4.98000" ixy="-0.00000" ixz="2.70000" iyy="-5.95200" iyz="-0.00000" izz="0.82800"/>
    </inertial>
    <visual>
      <geometry>
        <mesh filename="package://abb_on_axis/meshes/visual/axis.stl"/>
      </geometry>
      <material name="">
        <color rgba="0.7058823 0.6901961 0.6313725 1"/>
      </material>
    </visual>
    <collision>
      <geometry>
        <mesh filename="package://abb_on_axis/meshes/collision/axis.stl"/>
      </geometry>
      <material name="">
        <color rgba="0.7058823 0.6901961 0.6313725 1"/>
      </material>
    </collision>
  </link>
  <link name="r1_cart">
    <inertial>
      <origin xyz="0.0 0.0 0.0"/>
      <mass value="120.00000"/>
      <inertia ixx="-4.98000" ixy="-0.00000" ixz="2.70000" iyy="-5.95200" iyz="-0.00000" izz="0.82800"/>
    </inertial>
    <visual>
      <geometry>
        <mesh filename="package://abb_on_axis/meshes/visual/cart.stl"/>
      </geometry>
      <material name="">
        <color rgba="0.8392157 0.8352941 0.7921569 1"/>
      </material>
    </visual>
    <collision>
      <geometry>
        <mesh filename="package://abb_on_axis/meshes/collision/cart.stl"/>
      </geometry>
      <material name="">
        <color rgba="0.8392157 0.8352941 0.7921569 1"/>
      </material>
    </collision>
  </link>
  <!-- linear axis joint list -->
  <joint name="r1_cart_joint" type="prismatic">
    <parent link="r1_axis"/>
    <child link="r1_cart"/>
    <origin rpy="0 0 0 " xyz="0 0 0"/>
    <axis xyz="1 0 0"/>
    <limit effort="100000" lower="0" upper="3.9" velocity="2.618"/>
    <dynamics damping="0.2" friction="0"/>
  </joint>
  <joint name="r1_abb_joint" type="fixed">
    <parent link="r1_cart"/>
    <child link="r1_base_link"/>
    <origin rpy="0 0 1.5707963267948966 " xyz="0 0 0 "/>
    <dynamics damping="0.2" friction="0"/>
  </joint>
  <!-- ARE WE MISSING A WORLD TO AXIS fixed joint? for only the abb_on_axis group?-->
  <!-- GRIPPER -->
  <!-- gripper link list -->
  <link name="r1_gripper">
    <visual>
      <geometry>
        <mesh filename="package://abb_irb4600_40_255/meshes/visual/calibration_tool_R1.stl"/>
      </geometry>
      <material name="">
        <color rgba="1.0 0.8 0.796078431372549 1"/>
      </material>
    </visual>
    <collision>
      <geometry>
        <mesh filename="package://abb_irb4600_40_255/meshes/collision/calibration_tool_R1.stl"/>
      </geometry>
      <material name="">
        <color rgba="1.0 0.8 0.796078431372549 1"/>
      </material>
    </collision>
  </link>
  <link name="r1_tcp"/>
  <!-- gripper joint list -->
  <joint name="r1_gripper_joint" type="fixed">
    <parent link="r1_tool0"/>
    <child link="r1_gripper"/>
    <origin rpy="0 0 0" xyz="0 0 0"/>
  </joint>
  <joint name="r1_tcp_joint" type="fixed">
    <parent link="r1_gripper"/>
    <child link="r1_tcp"/>
    <origin rpy="0 0 0" xyz="-0.000441033 -0.0000930574 0.1642732"/>
  </joint>
  <!-- IRB4600 -->
  <!-- irb4600 link list -->
  <link name="r1_base_link">
    <inertial>
      <origin xyz="0.0 0.0 0.0"/>
      <mass value="120.00000"/>
      <inertia ixx="-4.98000" ixy="-0.00000" ixz="2.70000" iyy="-5.95200" iyz="-0.00000" izz="0.82800"/>
    </inertial>
    <visual>
      <geometry>
        <mesh filename="package://abb_irb4600_40_255/meshes/visual/base_link.stl"/>
      </geometry>
      <material name="">
        <color rgba="0.8392157 0.8352941 0.7921569 1"/>
      </material>
    </visual>
    <collision>
      <geometry>
        <mesh filename="package://abb_irb4600_40_255/meshes/collision/base_link.stl"/>
      </geometry>
      <material name="">
        <color rgba="0.8392157 0.8352941 0.7921569 1"/>
      </material>
    </collision>
  </link>
  <link name="r1_link_1">
    <inertial>
      <origin xyz="0.18000 0.00000 0.50000"/>
      <mass value="120.00000"/>
      <inertia ixx="-4.98000" ixy="-0.00000" ixz="2.70000" iyy="-5.95200" iyz="-0.00000" izz="0.82800"/>
    </inertial>
    <visual>
      <geometry>
        <mesh filename="package://abb_irb4600_40_255/meshes/visual/link_1.stl"/>
      </geometry>
      <material name="">
        <color rgba="0.8392157 0.8352941 0.7921569 1"/>
      </material>
    </visual>
    <collision>
      <geometry>
        <mesh filename="package://abb_irb4600_40_255/meshes/collision/link_1.stl"/>
      </geometry>
      <material name="">
        <color rgba="0.8392157 0.8352941 0.7921569 1"/>
      </material>
    </collision>
  </link>
  <link name="r1_link_2">
    <inertial>
      <origin xyz="0.94000 0.08000 -0.34000"/>
      <mass value="120.00000"/>
      <inertia ixx="-2.96000" ixy="2.25600" ixz="-9.58800" iyy="-18.72601" iyz="-0.81600" izz="-14.95000"/>
    </inertial>
    <visual>
      <geometry>
        <mesh filename="package://abb_irb4600_40_255/meshes/visual/link_2.stl"/>
      </geometry>
      <material name="">
        <color rgba="0.8392157 0.8352941 0.7921569 1"/>
      </material>
    </visual>
    <collision>
      <geometry>
        <mesh filename="package://abb_irb4600_40_255/meshes/collision/link_2.stl"/>
      </geometry>
      <material name="">
        <color rgba="0.8392157 0.8352941 0.7921569 1"/>
      </material>
    </collision>
  </link>
  <link name="r1_link_3">
    <inertial>
      <origin xyz="0.07000 -0.26600 0.08800"/>
      <mass value="120.00000"/>
      <inertia ixx="1.34500" ixy="-0.55860" ixz="0.18480" iyy="4.65068" iyz="-0.70224" izz="2.76032"/>
    </inertial>
    <visual>
      <geometry>
        <mesh filename="package://abb_irb4600_40_255/meshes/visual/link_3.stl"/>
      </geometry>
      <material name="">
        <color rgba="0.8392157 0.8352941 0.7921569 1"/>
      </material>
    </visual>
    <collision>
      <geometry>
        <mesh filename="package://abb_irb4600_40_255/meshes/collision/link_3.stl"/>
      </geometry>
      <material name="">
        <color rgba="0.8392157 0.8352941 0.7921569 1"/>
      </material>
    </collision>
  </link>
  <link name="r1_link_4">
    <inertial>
      <origin xyz="0.00000 0.00000 1.00000"/>
      <mass value="40.00000"/>
      <inertia ixx="-8.00000" ixy="-0.00000" ixz="-0.00000" iyy="-8.00000" iyz="-0.00000" izz="0.48200"/>
    </inertial>
    <visual>
      <geometry>
        <mesh filename="package://abb_irb4600_40_255/meshes/visual/link_4.stl"/>
      </geometry>
      <material name="">
        <color rgba="0.8392157 0.8352941 0.7921569 1"/>
      </material>
    </visual>
    <collision>
      <geometry>
        <mesh filename="package://abb_irb4600_40_255/meshes/collision/link_4.stl"/>
      </geometry>
      <material name="">
        <color rgba="0.8392157 0.8352941 0.7921569 1"/>
      </material>
    </collision>
  </link>
  <link name="r1_link_5">
    <inertial>
      <origin xyz="0.14000 0.00000 0.00000"/>
      <mass value="10.00000"/>
      <inertia ixx="0.04000" ixy="-0.00000" ixz="-0.00000" iyy="-0.00900" iyz="-0.00000" izz="-0.00400"/>
    </inertial>
    <visual>
      <geometry>
        <mesh filename="package://abb_irb4600_40_255/meshes/visual/link_5.stl"/>
      </geometry>
      <material name="">
        <color rgba="0.8392157 0.8352941 0.7921569 1"/>
      </material>
    </visual>
    <collision>
      <geometry>
        <mesh filename="package://abb_irb4600_40_255/meshes/collision/link_5.stl"/>
      </geometry>
      <material name="">
        <color rgba="0.8392157 0.8352941 0.7921569 1"/>
      </material>
    </collision>
  </link>
  <link name="r1_link_6">
    <inertial>
      <origin xyz="0.08100 -0.09100 0.33200"/>
      <mass value="5.00000"/>
      <inertia ixx="-0.29652" ixy="-0.03686" ixz="0.09396" iyy="-0.28792" iyz="-0.10556" izz="-0.04621"/>
    </inertial>
    <visual>
      <geometry>
        <mesh filename="package://abb_irb4600_40_255/meshes/visual/link_6.stl"/>
      </geometry>
      <material name="">
        <color rgba="0.8392157 0.8352941 0.7921569 1"/>
      </material>
    </visual>
    <collision>
      <geometry>
        <mesh filename="package://abb_irb4600_40_255/meshes/collision/link_6.stl"/>
      </geometry>
      <material name="">
        <color rgba="0.8392157 0.8352941 0.7921569 1"/>
      </material>
    </collision>
  </link>
  <link name="r1_tool0"/>
  <!-- irb4600 joint list -->
  <joint name="r1_joint_1" type="revolute">
    <parent link="r1_base_link"/>
    <child link="r1_link_1"/>
    <origin rpy="0 0 0" xyz="0 0 0.495"/>
    <axis xyz="0 0 1"/>
    <limit effort="100000" lower="-3.141592653589793" upper="3.141592653589793" velocity="2.618"/>
    <dynamics damping="0.2" friction="0"/>
  </joint>
  <joint name="r1_joint_2" type="revolute">
    <parent link="r1_link_1"/>
    <child link="r1_link_2"/>
    <origin rpy="0 0 0" xyz="0.175 0 0"/>
    <axis xyz="0 1 0"/>
    <limit effort="100000" lower="-1.3089969389957472" upper="2.6179938779914944" velocity="2.618"/>
    <dynamics damping="0.2" friction="0"/>
  </joint>
  <joint name="r1_joint_3" type="revolute">
    <parent link="r1_link_2"/>
    <child link="r1_link_3"/>
    <origin rpy="0 0 0" xyz="0 0 1.095"/>
    <axis xyz="0 1 0"/>
    <limit effort="100000" lower="-3.141592653589793" upper="1.3089969389957472" velocity="2.618"/>
    <dynamics damping="0.2" friction="0"/>
  </joint>
  <joint name="r1_joint_4" type="revolute">
    <parent link="r1_link_3"/>
    <child link="r1_link_4"/>
    <origin rpy="0 0 0" xyz="0 0 0.175"/>
    <axis xyz="1 0 0"/>
    <limit effort="10000" lower="-6.981317007977318" upper="6.981317007977318" velocity="6.2832"/>
    <dynamics damping="0.2" friction="0"/>
  </joint>
  <joint name="r1_joint_5" type="revolute">
    <parent link="r1_link_4"/>
    <child link="r1_link_5"/>
    <origin rpy="0 0 0" xyz="1.270 0 0"/>
    <axis xyz="0 1 0"/>
    <limit effort="100000" lower="-2.181661564992912" upper="2.0943951023931953" velocity="6.2832"/>
    <dynamics damping="0.2" friction="0"/>
  </joint>
  <joint name="r1_joint_6" type="revolute">
    <parent link="r1_link_5"/>
    <child link="r1_link_6"/>
    <origin rpy="0 0 0" xyz="0.135 0 0"/>
    <axis xyz="1 0 0"/>
    <limit effort="100000" lower="-6.981317007977318" upper="6.981317007977318" velocity="7.854"/>
    <dynamics damping="0.2" friction="0"/>
  </joint>
  <joint name="r1_joint_6-tool0" type="fixed">
    <parent link="r1_link_6"/>
    <child link="r1_tool0"/>
    <origin rpy="0 1.5707963267948966 0" xyz="0 0 0"/>
  </joint>
  <!-- -->
  <!-- IRB4600 base_link to ABB World Coordinates transform -->
  <link name="r1_base"/>
  <joint name="r1_base_link-base" type="fixed">
    <parent link="r1_base_link"/>
    <child link="r1_base"/>
    <origin rpy="0 0 0" xyz="0 0 0"/>
  </joint>
  <!-- -->
  <!--ROBOT 2-->
  <joint name="r2_world_joint" type="fixed">
    <parent link="world"/>
    <child link="r2_axis"/>
    <origin rpy="0.0 0.0 0.0" xyz="0.0 0.00137 0.00036"/>
  </joint>
  <!-- Conversion were obtained from http://www.e-paint.co.uk/Lab_values.asp
       unless otherwise stated. -->
  <!-- Conversion were obtained from http://www.e-paint.co.uk/Lab_values.asp
       unless otherwise stated. -->
  <!-- LINEAR AXIS -->
  <!-- linear axis link list -->
  <link name="r2_axis">
    <inertial>
      <origin xyz="0.0 0.0 0.0"/>
      <mass value="120"/>
      <inertia ixx="-4.98000" ixy="-0.00000" ixz="2.70000" iyy="-5.95200" iyz="-0.00000" izz="0.82800"/>
    </inertial>
    <visual>
      <geometry>
        <mesh filename="package://abb_on_axis/meshes/visual/axis.stl"/>
      </geometry>
      <material name="">
        <color rgba="0.7058823 0.6901961 0.6313725 1"/>
      </material>
    </visual>
    <collision>
      <geometry>
        <mesh filename="package://abb_on_axis/meshes/collision/axis.stl"/>
      </geometry>
      <material name="">
        <color rgba="0.7058823 0.6901961 0.6313725 1"/>
      </material>
    </collision>
  </link>
  <link name="r2_cart">
    <inertial>
      <origin xyz="0.0 0.0 0.0"/>
      <mass value="120.00000"/>
      <inertia ixx="-4.98000" ixy="-0.00000" ixz="2.70000" iyy="-5.95200" iyz="-0.00000" izz="0.82800"/>
    </inertial>
    <visual>
      <geometry>
        <mesh filename="package://abb_on_axis/meshes/visual/cart.stl"/>
      </geometry>
      <material name="">
        <color rgba="0.8392157 0.8352941 0.7921569 1"/>
      </material>
    </visual>
    <collision>
      <geometry>
        <mesh filename="package://abb_on_axis/meshes/collision/cart.stl"/>
      </geometry>
      <material name="">
        <color rgba="0.8392157 0.8352941 0.7921569 1"/>
      </material>
    </collision>
  </link>
  <!-- linear axis joint list -->
  <joint name="r2_cart_joint" type="prismatic">
    <parent link="r2_axis"/>
    <child link="r2_cart"/>
    <origin rpy="0 0 0 " xyz="0 0 0"/>
    <axis xyz="1 0 0"/>
    <limit effort="100000" lower="0" upper="3.9" velocity="2.618"/>
    <dynamics damping="0.2" friction="0"/>
  </joint>
  <joint name="r2_abb_joint" type="fixed">
    <parent link="r2_cart"/>
    <child link="r2_base_link"/>
    <origin rpy="0 0 1.5707963267948966 " xyz="0 0 0 "/>
    <dynamics damping="0.2" friction="0"/>
  </joint>
  <!-- ARE WE MISSING A WORLD TO AXIS fixed joint? for only the abb_on_axis group?-->
  <!-- GRIPPER -->
  <!-- gripper link list -->
  <link name="r2_gripper">
    <visual>
      <geometry>
        <mesh filename="package://abb_irb4600_40_255/meshes/visual/calibration_tool_R2.stl"/>
      </geometry>
      <material name="">
        <color rgba="1.0 0.8 0.796078431372549 1"/>
      </material>
    </visual>
    <collision>
      <geometry>
        <mesh filename="package://abb_irb4600_40_255/meshes/collision/calibration_tool_R2.stl"/>
      </geometry>
      <material name="">
        <color rgba="1.0 0.8 0.796078431372549 1"/>
      </material>
    </collision>
  </link>
  <link name="r2_tcp"/>
  <!-- gripper joint list -->
  <joint name="r2_gripper_joint" type="fixed">
    <parent link="r2_tool0"/>
    <child link="r2_gripper"/>
    <origin rpy="0 0 0" xyz="0 0 0"/>
  </joint>
  <joint name="r2_tcp_joint" type="fixed">
    <parent link="r2_gripper"/>
    <child link="r2_tcp"/>
    <origin rpy="0 0 0" xyz="0.000473456 0.000169985 0.163856"/>
  </joint>
  <!-- IRB4600 -->
  <!-- irb4600 link list -->
  <link name="r2_base_link">
    <inertial>
      <origin xyz="0.0 0.0 0.0"/>
      <mass value="120.00000"/>
      <inertia ixx="-4.98000" ixy="-0.00000" ixz="2.70000" iyy="-5.95200" iyz="-0.00000" izz="0.82800"/>
    </inertial>
    <visual>
      <geometry>
        <mesh filename="package://abb_irb4600_40_255/meshes/visual/base_link.stl"/>
      </geometry>
      <material name="">
        <color rgba="0.8392157 0.8352941 0.7921569 1"/>
      </material>
    </visual>
    <collision>
      <geometry>
        <mesh filename="package://abb_irb4600_40_255/meshes/collision/base_link.stl"/>
      </geometry>
      <material name="">
        <color rgba="0.8392157 0.8352941 0.7921569 1"/>
      </material>
    </collision>
  </link>
  <link name="r2_link_1">
    <inertial>
      <origin xyz="0.18000 0.00000 0.50000"/>
      <mass value="120.00000"/>
      <inertia ixx="-4.98000" ixy="-0.00000" ixz="2.70000" iyy="-5.95200" iyz="-0.00000" izz="0.82800"/>
    </inertial>
    <visual>
      <geometry>
        <mesh filename="package://abb_irb4600_40_255/meshes/visual/link_1.stl"/>
      </geometry>
      <material name="">
        <color rgba="0.8392157 0.8352941 0.7921569 1"/>
      </material>
    </visual>
    <collision>
      <geometry>
        <mesh filename="package://abb_irb4600_40_255/meshes/collision/link_1.stl"/>
      </geometry>
      <material name="">
        <color rgba="0.8392157 0.8352941 0.7921569 1"/>
      </material>
    </collision>
  </link>
  <link name="r2_link_2">
    <inertial>
      <origin xyz="0.94000 0.08000 -0.34000"/>
      <mass value="120.00000"/>
      <inertia ixx="-2.96000" ixy="2.25600" ixz="-9.58800" iyy="-18.72601" iyz="-0.81600" izz="-14.95000"/>
    </inertial>
    <visual>
      <geometry>
        <mesh filename="package://abb_irb4600_40_255/meshes/visual/link_2.stl"/>
      </geometry>
      <material name="">
        <color rgba="0.8392157 0.8352941 0.7921569 1"/>
      </material>
    </visual>
    <collision>
      <geometry>
        <mesh filename="package://abb_irb4600_40_255/meshes/collision/link_2.stl"/>
      </geometry>
      <material name="">
        <color rgba="0.8392157 0.8352941 0.7921569 1"/>
      </material>
    </collision>
  </link>
  <link name="r2_link_3">
    <inertial>
      <origin xyz="0.07000 -0.26600 0.08800"/>
      <mass value="120.00000"/>
      <inertia ixx="1.34500" ixy="-0.55860" ixz="0.18480" iyy="4.65068" iyz="-0.70224" izz="2.76032"/>
    </inertial>
    <visual>
      <geometry>
        <mesh filename="package://abb_irb4600_40_255/meshes/visual/link_3.stl"/>
      </geometry>
      <material name="">
        <color rgba="0.8392157 0.8352941 0.7921569 1"/>
      </material>
    </visual>
    <collision>
      <geometry>
        <mesh filename="package://abb_irb4600_40_255/meshes/collision/link_3.stl"/>
      </geometry>
      <material name="">
        <color rgba="0.8392157 0.8352941 0.7921569 1"/>
      </material>
    </collision>
  </link>
  <link name="r2_link_4">
    <inertial>
      <origin xyz="0.00000 0.00000 1.00000"/>
      <mass value="40.00000"/>
      <inertia ixx="-8.00000" ixy="-0.00000" ixz="-0.00000" iyy="-8.00000" iyz="-0.00000" izz="0.48200"/>
    </inertial>
    <visual>
      <geometry>
        <mesh filename="package://abb_irb4600_40_255/meshes/visual/link_4.stl"/>
      </geometry>
      <material name="">
        <color rgba="0.8392157 0.8352941 0.7921569 1"/>
      </material>
    </visual>
    <collision>
      <geometry>
        <mesh filename="package://abb_irb4600_40_255/meshes/collision/link_4.stl"/>
      </geometry>
      <material name="">
        <color rgba="0.8392157 0.8352941 0.7921569 1"/>
      </material>
    </collision>
  </link>
  <link name="r2_link_5">
    <inertial>
      <origin xyz="0.14000 0.00000 0.00000"/>
      <mass value="10.00000"/>
      <inertia ixx="0.04000" ixy="-0.00000" ixz="-0.00000" iyy="-0.00900" iyz="-0.00000" izz="-0.00400"/>
    </inertial>
    <visual>
      <geometry>
        <mesh filename="package://abb_irb4600_40_255/meshes/visual/link_5.stl"/>
      </geometry>
      <material name="">
        <color rgba="0.8392157 0.8352941 0.7921569 1"/>
      </material>
    </visual>
    <collision>
      <geometry>
        <mesh filename="package://abb_irb4600_40_255/meshes/collision/link_5.stl"/>
      </geometry>
      <material name="">
        <color rgba="0.8392157 0.8352941 0.7921569 1"/>
      </material>
    </collision>
  </link>
  <link name="r2_link_6">
    <inertial>
      <origin xyz="0.08100 -0.09100 0.33200"/>
      <mass value="5.00000"/>
      <inertia ixx="-0.29652" ixy="-0.03686" ixz="0.09396" iyy="-0.28792" iyz="-0.10556" izz="-0.04621"/>
    </inertial>
    <visual>
      <geometry>
        <mesh filename="package://abb_irb4600_40_255/meshes/visual/link_6.stl"/>
      </geometry>
      <material name="">
        <color rgba="0.8392157 0.8352941 0.7921569 1"/>
      </material>
    </visual>
    <collision>
      <geometry>
        <mesh filename="package://abb_irb4600_40_255/meshes/collision/link_6.stl"/>
      </geometry>
      <material name="">
        <color rgba="0.8392157 0.8352941 0.7921569 1"/>
      </material>
    </collision>
  </link>
  <link name="r2_tool0"/>
  <!-- irb4600 joint list -->
  <joint name="r2_joint_1" type="revolute">
    <parent link="r2_base_link"/>
    <child link="r2_link_1"/>
    <origin rpy="0 0 0" xyz="0 0 0.495"/>
    <axis xyz="0 0 1"/>
    <limit effort="100000" lower="-3.141592653589793" upper="3.141592653589793" velocity="2.618"/>
    <dynamics damping="0.2" friction="0"/>
  </joint>
  <joint name="r2_joint_2" type="revolute">
    <parent link="r2_link_1"/>
    <child link="r2_link_2"/>
    <origin rpy="0 0 0" xyz="0.175 0 0"/>
    <axis xyz="0 1 0"/>
    <limit effort="100000" lower="-1.3089969389957472" upper="2.6179938779914944" velocity="2.618"/>
    <dynamics damping="0.2" friction="0"/>
  </joint>
  <joint name="r2_joint_3" type="revolute">
    <parent link="r2_link_2"/>
    <child link="r2_link_3"/>
    <origin rpy="0 0 0" xyz="0 0 1.095"/>
    <axis xyz="0 1 0"/>
    <limit effort="100000" lower="-3.141592653589793" upper="1.3089969389957472" velocity="2.618"/>
    <dynamics damping="0.2" friction="0"/>
  </joint>
  <joint name="r2_joint_4" type="revolute">
    <parent link="r2_link_3"/>
    <child link="r2_link_4"/>
    <origin rpy="0 0 0" xyz="0 0 0.175"/>
    <axis xyz="1 0 0"/>
    <limit effort="10000" lower="-6.981317007977318" upper="6.981317007977318" velocity="6.2832"/>
    <dynamics damping="0.2" friction="0"/>
  </joint>
  <joint name="r2_joint_5" type="revolute">
    <parent link="r2_link_4"/>
    <child link="r2_link_5"/>
    <origin rpy="0 0 0" xyz="1.270 0 0"/>
    <axis xyz="0 1 0"/>
    <limit effort="100000" lower="-2.181661564992912" upper="2.0943951023931953" velocity="6.2832"/>
    <dynamics damping="0.2" friction="0"/>
  </joint>
  <joint name="r2_joint_6" type="revolute">
    <parent link="r2_link_5"/>
    <child link="r2_link_6"/>
    <origin rpy="0 0 0" xyz="0.135 0 0"/>
    <axis xyz="1 0 0"/>
    <limit effort="100000" lower="-6.981317007977318" upper="6.981317007977318" velocity="7.854"/>
    <dynamics damping="0.2" friction="0"/>
  </joint>
  <joint name="r2_joint_6-tool0" type="fixed">
    <parent link="r2_link_6"/>
    <child link="r2_tool0"/>
    <origin rpy="0 1.5707963267948966 0" xyz="0 0 0"/>
  </joint>
  <!-- -->
  <!-- IRB4600 base_link to ABB World Coordinates transform -->
  <link name="r2_base"/>
  <joint name="r2_base_link-base" type="fixed">
    <parent link="r2_base_link"/>
    <child link="r2_base"/>
    <origin rpy="0 0 0" xyz="0 0 0"/>
  </joint>
  <!-- -->
  <!--ROBOT 3-->
  <joint name="r3_world_joint" type="fixed">
    <parent link="world"/>
    <child link="r3_base_link"/>
    <origin rpy="0.0 0.0 3.14159" xyz="4.885 1.7193 -0.3774"/>
  </joint>
  <!-- GRIPPER -->
  <!-- gripper link list -->
  <link name="r3_gripper">
    <visual>
      <geometry>
        <mesh filename="package://abb_irb7600_400_255/meshes/visual/calibration_tool.stl"/>
      </geometry>
      <material name="">
        <color rgba="1.0 0.8 0.796078431372549 1"/>
      </material>
    </visual>
    <collision>
      <geometry>
        <mesh filename="package://abb_irb7600_400_255/meshes/collision/calibration_tool.stl"/>
      </geometry>
      <material name="">
        <color rgba="1.0 0.8 0.796078431372549 1"/>
      </material>
    </collision>
  </link>
  <link name="r3_tcp"/>
  <!-- gripper joint list -->
  <joint name="r3_gripper_joint" type="fixed">
    <parent link="r3_tool0"/>
    <child link="r3_gripper"/>
    <origin rpy="0 0 0" xyz="0 0 0"/>
  </joint>
  <joint name="r3_tcp_joint" type="fixed">
    <parent link="r3_gripper"/>
    <child link="r3_tcp"/>
    <origin rpy="0 0 0" xyz="0.583723 0.0236933 77.9321"/>
  </joint>
  <!-- IRB7600-->
  <!-- irb7600 link list -->
  <link name="r3_base_link">
    <visual>
      <geometry>
        <mesh filename="package://abb_irb7600_400_255/meshes/visual/base_link.stl"/>
      </geometry>
      <material name="">
        <color rgba="0.8392157 0.8352941 0.7921569 1"/>
      </material>
    </visual>
    <collision>
      <geometry>
        <mesh filename="package://abb_irb7600_400_255/meshes/collision/base_link.stl"/>
      </geometry>
      <material name="">
        <color rgba="0.8392157 0.8352941 0.7921569 1"/>
      </material>
    </collision>
  </link>
  <link name="r3_link_1">
    <visual>
      <geometry>
        <mesh filename="package://abb_irb7600_400_255/meshes/visual/link_1.stl"/>
      </geometry>
      <material name="">
        <color rgba="0.8392157 0.8352941 0.7921569 1"/>
      </material>
    </visual>
    <collision>
      <geometry>
        <mesh filename="package://abb_irb7600_400_255/meshes/collision/link_1.stl"/>
      </geometry>
      <material name="">
        <color rgba="0.8392157 0.8352941 0.7921569 1"/>
      </material>
    </collision>
  </link>
  <link name="r3_link_2">
    <visual>
      <geometry>
        <mesh filename="package://abb_irb7600_400_255/meshes/visual/link_2.stl"/>
      </geometry>
      <material name="">
        <color rgba="0.8392157 0.8352941 0.7921569 1"/>
      </material>
    </visual>
    <collision>
      <geometry>
        <mesh filename="package://abb_irb7600_400_255/meshes/collision/link_2.stl"/>
      </geometry>
      <material name="">
        <color rgba="0.8392157 0.8352941 0.7921569 1"/>
      </material>
    </collision>
  </link>
  <link name="r3_link_3">
    <visual>
      <geometry>
        <mesh filename="package://abb_irb7600_400_255/meshes/visual/link_3.stl"/>
      </geometry>
      <material name="">
        <color rgba="0.8392157 0.8352941 0.7921569 1"/>
      </material>
    </visual>
    <collision>
      <geometry>
        <mesh filename="package://abb_irb7600_400_255/meshes/collision/link_3.stl"/>
      </geometry>
      <material name="">
        <color rgba="0.8392157 0.8352941 0.7921569 1"/>
      </material>
    </collision>
  </link>
  <link name="r3_link_4">
    <visual>
      <geometry>
        <mesh filename="package://abb_irb7600_400_255/meshes/visual/link_4.stl"/>
      </geometry>
      <material name="">
        <color rgba="0.8392157 0.8352941 0.7921569 1"/>
      </material>
    </visual>
    <collision>
      <geometry>
        <mesh filename="package://abb_irb7600_400_255/meshes/collision/link_4.stl"/>
      </geometry>
      <material name="">
        <color rgba="0.8392157 0.8352941 0.7921569 1"/>
      </material>
    </collision>
  </link>
  <link name="r3_link_5">
    <visual>
      <geometry>
        <mesh filename="package://abb_irb7600_400_255/meshes/visual/link_5.stl"/>
      </geometry>
      <material name="">
        <color rgba="0.8392157 0.8352941 0.7921569 1"/>
      </material>
    </visual>
    <collision>
      <geometry>
        <mesh filename="package://abb_irb7600_400_255/meshes/collision/link_5.stl"/>
      </geometry>
      <material name="">
        <color rgba="0.8392157 0.8352941 0.7921569 1"/>
      </material>
    </collision>
  </link>
  <link name="r3_link_6">
    <visual>
      <geometry>
        <mesh filename="package://abb_irb7600_400_255/meshes/visual/link_6.stl"/>
      </geometry>
      <material name="">
        <color rgba="0.8392157 0.8352941 0.7921569 1"/>
      </material>
    </visual>
    <collision>
      <geometry>
        <mesh filename="package://abb_irb7600_400_255/meshes/collision/link_6.stl"/>
      </geometry>
      <material name="">
        <color rgba="0.8392157 0.8352941 0.7921569 1"/>
      </material>
    </collision>
  </link>
  <link name="r3_balancer_piston">
    <visual>
      <geometry>
        <mesh filename="package://abb_irb7600_400_255/meshes/visual/balancer_piston.stl"/>
      </geometry>
      <material name="">
        <color rgba="0.8392157 0.8352941 0.7921569 1"/>
      </material>
    </visual>
    <collision>
      <geometry>
        <mesh filename="package://abb_irb7600_400_255/meshes/collision/balancer_piston.stl"/>
      </geometry>
      <material name="">
        <color rgba="0.8392157 0.8352941 0.7921569 1"/>
      </material>
    </collision>
  </link>
  <link name="r3_tool0"/>
  <!-- end of link list -->
  <!-- joint list -->
  <joint name="r3_joint_1" type="revolute">
    <parent link="r3_base_link"/>
    <child link="r3_link_1"/>
    <origin rpy="0 0 0" xyz="0 0 0"/>
    <axis xyz="0 0 1"/>
    <limit effort="0" lower="-3.141592653589793" upper="3.141592653589793" velocity="1.7453292519943295"/>
  </joint>
  <joint name="r3_joint_2" type="revolute">
    <parent link="r3_link_1"/>
    <child link="r3_link_2"/>
    <origin rpy="0 0 0" xyz="0.4100 0 0.7797"/>
    <axis xyz="0 1 0"/>
    <limit effort="0" lower="-1.0471975511965976" upper="1.4835298641951802" velocity="1.0471975511965976"/>
  </joint>
  <joint name="r3_joint_3" type="revolute">
    <parent link="r3_link_2"/>
    <child link="r3_link_3"/>
    <origin rpy="0 0 0" xyz="0 0 1.075"/>
    <axis xyz="0 1 0"/>
    <limit effort="0" lower="-3.141592653589793" upper="1.0471975511965976" velocity="1.0471975511965976"/>
  </joint>
  <joint name="r3_joint_4" type="revolute">
    <parent link="r3_link_3"/>
    <child link="r3_link_4"/>
    <origin rpy="0 0 0" xyz="0.1749 0 0.1650"/>
    <axis xyz="1 0 0"/>
    <limit effort="0" lower="-5.235987755982989" upper="5.235987755982989" velocity="1.7453292519943295"/>
  </joint>
  <joint name="r3_joint_5" type="revolute">
    <parent link="r3_link_4"/>
    <child link="r3_link_5"/>
    <origin rpy="0 0 0" xyz="0.8821 0 0"/>
    <axis xyz="0 1 0"/>
    <limit effort="0" lower="-1.7453292519943295" upper="1.7453292519943295" velocity="1.7453292519943295"/>
  </joint>
  <joint name="r3_joint_6" type="revolute">
    <parent link="r3_link_5"/>
    <child link="r3_link_6"/>
    <origin rpy="0 0 0" xyz="0.2490 0 0"/>
    <axis xyz="1 0 0"/>
    <limit effort="0" lower="-6.283185307179586" upper="6.283185307179586" velocity="3.3161255787892263"/>
  </joint>
  <joint name="r3_joint_6-tool0" type="fixed">
    <parent link="r3_link_6"/>
    <child link="r3_tool0"/>
    <origin rpy="0 1.5707963267948966 0" xyz="0 0 0"/>
  </joint>
  <joint name="r3_joint_balancer_piston" type="fixed">
    <parent link="r3_link_1"/>
    <child link="r3_balancer_piston"/>
    <origin rpy="0 0 0" xyz="-0.3779 0 0.6536"/>
  </joint>
  <!-- -->
  <!-- ROS-Industrial 'base' frame: base_link to ABB World Coordinates transform -->
  <link name="r3_base"/>
  <joint name="r3_base_link-base" type="fixed">
    <parent link="r3_base_link"/>
    <child link="r3_base"/>
    <origin rpy="0 0 0" xyz="0 0 0"/>
  </joint>
</robot>
